Workbook

Sheet Overview
A1: Unintended braking — scenario-based residual-risk example
A2: SYNTHETIC, ILLUSTRATIVE NUMBERS. Shows the calculation chain, not any real system.
A4: Validation target | B4: Rate of MAIS2+ injuries from rear-end collisions caused by unintended (phantom) braking of the ego vehicle ≤ A_H per operating hour, at confidence C.
A5: Hazardous behaviour (HB) | B5: Ego brakes without a valid reason (perception false positive → planner brake request).
A6: Hazardous event (HE) | B6: HB while a following vehicle is close enough that it cannot avoid a rear-end collision.
A7: ODD partition | B7: 100 logical scenarios = 5 trigger contexts × 4 speed bands × 5 follower-headway classes. They are mutually exclusive and their time shares sum to 1 (checked on Summary).
A8: Risk equation | B8: R = Σ_l share_l · λ_HB(trigger, speed) · P(collision | HB, l) · E[P(MAIS2+ | Δv) | collision, l]
A9: Where each term comes from | B9: share_l: fleet operations logs (context tagging) · λ_HB: open-loop replay of targeted logs through perception+planner, counting unintended brake requests · P(collision|HB): kinematic Monte Carlo of the follower's response · P(MAIS2+|Δv): injury risk curve (illustrative; real curves are fit to accident data).
A10: Key modelling assumption | B10: λ_HB depends on trigger context and speed, not on whether a follower is present (forward perception does not see the follower). So 20 evidence cells serve 100 scenarios.
A11: Three ways to judge the target | B11: (1) Point estimate — not acceptable as evidence. (2) Bonferroni: simultaneous upper bounds on every estimated term, multiplied — rigorous but very conservative. (3) Bayesian posterior 95% quantile of R (Jeffreys priors) — computed in ub_sim.py.
A12: Concrete scenarios | B12: 1,000 made-up concrete scenarios (10 per logical scenario). Parameters drawn from an importance-sampling proposal q (later reactions, longer phantom brakes, shorter headways) through a Gaussian copula; each carries the exact weight w = f(θ)/q(θ) so the 10 runs estimate the real-world probability.
A13: Parameter dependence | B13: Ego speed, follower time headway, follower reaction time and follower deceleration are coupled by a Gaussian copula (see sheet 'Gaussian Copula'): each keeps its own marginal distribution, the correlation matrix R sets how they move together.
A14: Sheets | B14: Inputs → HB Evidence (20 cells) → Scenarios (100 logical) → Concrete Scenarios (1,000) → Gaussian Copula → Summary → Validation Targets.
A15: Colour code | B15: Blue on yellow = input/assumption · blue = evidence value (from data or simulation) · black = formula · green = link to another sheet · grey italic = synthetic ground truth, for comparison only (unknown in reality).
A16: Verdict (from Summary)
A17: Point estimate | B17: =Summary!D14 -> meets budget (point only — not a valid claim)
A18: Bonferroni upper bound | B18: =Summary!D15 -> FAIL — evidence insufficient, see Validation Targets
A19: Bayesian 95% quantile | B19: =Summary!D16 -> PASS at 95% posterior (prior must be justified to the assessor)

Sheet Inputs
A1: Inputs and assumptions
A2: Edit blue-on-yellow cells. Everything else recalculates.
A4: Parameter | B4: Value | C4: Note
A5: Acceptance criterion A_H [MAIS2+ injuries / h] | B5: 1e-07 | C5: Illustrative. In practice from Clause 6 (e.g. GAMAB vs. human rear-end injury rate in the same ODD).
A6: Confidence C | B6: 0.95 | C6: Applies to the overall claim.
A7: Reserve for unknown triggers ε (share of A_H) | B7: 0.1 | C7: Budget held back for HB from triggering conditions not in the taxonomy (Clause 11); bounded by field driving.
A8: Number of evidence cells (λ bounds) | B8: =COUNTA('HB Evidence'!A6:A25) -> 20 | C8: Formula
A9: Number of scenarios (collision-probability bounds) | B9: =COUNTA(Scenarios!A6:A105) -> 100 | C9: Formula
A10: Per-bound confidence C_b (Bonferroni) | B10: =1-(1-B6)/(B8+B9) -> 0.99958333 | C10: Simultaneous bounds: Σ(1−C_b) = 1−C over all estimated terms.
A11: Known-scenario budget (1−ε)·A_H | B11: =(1-B7)*B5 -> 9e-08 | C11: Formula
A12: Injury curve: Δv at 50% MAIS2+ [km/h] | B12: 45 | C12: Illustrative logistic P(MAIS2+|Δv) = 1/(1+exp(−(Δv−Δv50)/s)). Drives the Concrete Scenarios sheet live; the 2,000-run column in Scenarios was computed with the build-time value.
A13: Injury curve: scale s [km/h] | B13: 7 | C13: Illustrative.
A14: Trigger context | B14: Time share | C14: Source
A15: Clear road, no trigger | B15: 0.8 | C15: Synthetic. Real: map + weather + sun-angle tagging of fleet operation logs.
A16: Overhead structure (bridge, gantry) | B16: 0.05 | C16: Synthetic. Real: map + weather + sun-angle tagging of fleet operation logs.
A17: Low sun / hard shadow | B17: 0.07 | C17: Synthetic. Real: map + weather + sun-angle tagging of fleet operation logs.
A18: Spray / heavy rain | B18: 0.05 | C18: Synthetic. Real: map + weather + sun-angle tagging of fleet operation logs.
A19: Roadside clutter / debris | B19: 0.03 | C19: Synthetic. Real: map + weather + sun-angle tagging of fleet operation logs.
A20: Sum (must be 100%) | B20: =SUM(B15:B19) -> 1
A22: Ego speed band | B22: Time share
A23: 20–35 km/h | B23: 0.35 | C23: Synthetic.
A24: 35–55 km/h | B24: 0.4 | C24: Synthetic.
A25: 55–75 km/h | B25: 0.15 | C25: Synthetic.
A26: 75–95 km/h | B26: 0.1 | C26: Synthetic.
A27: Sum (must be 100%) | B27: =SUM(B23:B26) -> 1
A29: Follower headway class | B29: Time share
A30: No follower within 3 s | B30: 0.45 | C30: Synthetic. Real: rear radar / camera tracks in fleet logs.
A31: Follower 2–3 s | B31: 0.2 | C31: Synthetic. Real: rear radar / camera tracks in fleet logs.
A32: Follower 1.5–2 s | B32: 0.15 | C32: Synthetic. Real: rear radar / camera tracks in fleet logs.
A33: Follower 1–1.5 s | B33: 0.13 | C33: Synthetic. Real: rear radar / camera tracks in fleet logs.
A34: Follower < 1 s | B34: 0.07 | C34: Synthetic. Real: rear radar / camera tracks in fleet logs.
A35: Sum (must be 100%) | B35: =SUM(B30:B34) -> 1
A37: Independence assumption | B37: Scenario share = product of the three factor shares. In reality the factors are correlated (e.g. spray and speed, headway and speed) — measure joint shares directly or model the dependence (copula).

Sheet HB Evidence
A1: Hazardous-behaviour rate per trigger context × speed band
A2: Open-loop replay of targeted logs through perception + planner. k = unintended brake requests observed in h hours.
A5: Cell | B5: Trigger context | C5: Speed band | D5: Replay hours h | E5: Events k | F5: λ̂ = k/h [1/h] | G5: λ upper, single 95% [1/h] | H5: λ upper, Bonferroni C_b [1/h] | I5: True λ (synthetic) [1/h] | J5: Harm weight G (upper) [h⁻¹ per λ] | K5: Point risk of cell [1/h]
A6: T1S1 | B6: Clear road, no trigger | C6: 20–35 km/h | D6: 12000 | E6: 0 | F6: =E6/D6 -> 0 | G6: =CHIINV(1-Inputs!$B$6,2*(E6+1))/2/D6 -> 0.00024964436 | H6: =CHIINV(1-Inputs!$B$10,2*(E6+1))/2/D6 -> 0.000648602 | I6: 2e-05 | J6: =SUMIF(Scenarios!$E$6:$E$105,A6,Scenarios!$V$6:$V$105) -> 0.00017961987 | K6: =SUMIF(Scenarios!$E$6:$E$105,A6,Scenarios!$R$6:$R$105) -> 0
A7: T1S2 | B7: Clear road, no trigger | C7: 35–55 km/h | D7: 14000 | E7: 0 | F7: =E7/D7 -> 0 | G7: =CHIINV(1-Inputs!$B$6,2*(E7+1))/2/D7 -> 0.00021398088 | H7: =CHIINV(1-Inputs!$B$10,2*(E7+1))/2/D7 -> 0.00055594457 | I7: 2e-05 | J7: =SUMIF(Scenarios!$E$6:$E$105,A7,Scenarios!$V$6:$V$105) -> 0.00018368472 | K7: =SUMIF(Scenarios!$E$6:$E$105,A7,Scenarios!$R$6:$R$105) -> 0
A8: T1S3 | B8: Clear road, no trigger | C8: 55–75 km/h | D8: 6000 | E8: 0 | F8: =E8/D8 -> 0 | G8: =CHIINV(1-Inputs!$B$6,2*(E8+1))/2/D8 -> 0.00049928871 | H8: =CHIINV(1-Inputs!$B$10,2*(E8+1))/2/D8 -> 0.001297204 | I8: 2.4e-05 | J8: =SUMIF(Scenarios!$E$6:$E$105,A8,Scenarios!$V$6:$V$105) -> 3.8232587e-05 | K8: =SUMIF(Scenarios!$E$6:$E$105,A8,Scenarios!$R$6:$R$105) -> 0
A9: T1S4 | B9: Clear road, no trigger | C9: 75–95 km/h | D9: 4000 | E9: 0 | F9: =E9/D9 -> 0 | G9: =CHIINV(1-Inputs!$B$6,2*(E9+1))/2/D9 -> 0.00074893307 | H9: =CHIINV(1-Inputs!$B$10,2*(E9+1))/2/D9 -> 0.001945806 | I9: 3e-05 | J9: =SUMIF(Scenarios!$E$6:$E$105,A9,Scenarios!$V$6:$V$105) -> 4.3909283e-05 | K9: =SUMIF(Scenarios!$E$6:$E$105,A9,Scenarios!$R$6:$R$105) -> 0
A10: T2S1 | B10: Overhead structure (bridge, gantry) | C10: 20–35 km/h | D10: 3000 | E10: 1 | F10: =E10/D10 -> 0.00033333333 | G10: =CHIINV(1-Inputs!$B$6,2*(E10+1))/2/D10 -> 0.0015812882 | H10: =CHIINV(1-Inputs!$B$10,2*(E10+1))/2/D10 -> 0.0033996844 | I10: 0.0004 | J10: =SUMIF(Scenarios!$E$6:$E$105,A10,Scenarios!$V$6:$V$105) -> 1.1190566e-05 | K10: =SUMIF(Scenarios!$E$6:$E$105,A10,Scenarios!$R$6:$R$105) -> 2.8987815e-09
A11: T2S2 | B11: Overhead structure (bridge, gantry) | C11: 35–55 km/h | D11: 4000 | E11: 1 | F11: =E11/D11 -> 0.00025 | G11: =CHIINV(1-Inputs!$B$6,2*(E11+1))/2/D11 -> 0.0011859661 | H11: =CHIINV(1-Inputs!$B$10,2*(E11+1))/2/D11 -> 0.0025497633 | I11: 0.0004 | J11: =SUMIF(Scenarios!$E$6:$E$105,A11,Scenarios!$V$6:$V$105) -> 1.0105589e-05 | K11: =SUMIF(Scenarios!$E$6:$E$105,A11,Scenarios!$R$6:$R$105) -> 1.6843687e-09
A12: T2S3 | B12: Overhead structure (bridge, gantry) | C12: 55–75 km/h | D12: 2500 | E12: 1 | F12: =E12/D12 -> 0.0004 | G12: =CHIINV(1-Inputs!$B$6,2*(E12+1))/2/D12 -> 0.0018975458 | H12: =CHIINV(1-Inputs!$B$10,2*(E12+1))/2/D12 -> 0.0040796213 | I12: 0.00048 | J12: =SUMIF(Scenarios!$E$6:$E$105,A12,Scenarios!$V$6:$V$105) -> 1.7291049e-06 | K12: =SUMIF(Scenarios!$E$6:$E$105,A12,Scenarios!$R$6:$R$105) -> 3.4922726e-10
A13: T2S4 | B13: Overhead structure (bridge, gantry) | C13: 75–95 km/h | D13: 2000 | E13: 4 | F13: =E13/D13 -> 0.002 | G13: =CHIINV(1-Inputs!$B$6,2*(E13+1))/2/D13 -> 0.0045767595 | H13: =CHIINV(1-Inputs!$B$10,2*(E13+1))/2/D13 -> 0.0079741032 | I13: 0.0006 | J13: =SUMIF(Scenarios!$E$6:$E$105,A13,Scenarios!$V$6:$V$105) -> 4.1401308e-07 | K13: =SUMIF(Scenarios!$E$6:$E$105,A13,Scenarios!$R$6:$R$105) -> 2.8640795e-10
A14: T3S1 | B14: Low sun / hard shadow | C14: 20–35 km/h | D14: 3000 | E14: 1 | F14: =E14/D14 -> 0.00033333333 | G14: =CHIINV(1-Inputs!$B$6,2*(E14+1))/2/D14 -> 0.0015812882 | H14: =CHIINV(1-Inputs!$B$10,2*(E14+1))/2/D14 -> 0.0033996844 | I14: 0.0002 | J14: =SUMIF(Scenarios!$E$6:$E$105,A14,Scenarios!$V$6:$V$105) -> 1.5566362e-05 | K14: =SUMIF(Scenarios!$E$6:$E$105,A14,Scenarios!$R$6:$R$105) -> 3.9577985e-09
A15: T3S2 | B15: Low sun / hard shadow | C15: 35–55 km/h | D15: 3500 | E15: 0 | F15: =E15/D15 -> 0 | G15: =CHIINV(1-Inputs!$B$6,2*(E15+1))/2/D15 -> 0.00085592351 | H15: =CHIINV(1-Inputs!$B$10,2*(E15+1))/2/D15 -> 0.0022237783 | I15: 0.0002 | J15: =SUMIF(Scenarios!$E$6:$E$105,A15,Scenarios!$V$6:$V$105) -> 1.6647479e-05 | K15: =SUMIF(Scenarios!$E$6:$E$105,A15,Scenarios!$R$6:$R$105) -> 0
A16: T3S3 | B16: Low sun / hard shadow | C16: 55–75 km/h | D16: 2000 | E16: 0 | F16: =E16/D16 -> 0 | G16: =CHIINV(1-Inputs!$B$6,2*(E16+1))/2/D16 -> 0.0014978661 | H16: =CHIINV(1-Inputs!$B$10,2*(E16+1))/2/D16 -> 0.003891612 | I16: 0.00024 | J16: =SUMIF(Scenarios!$E$6:$E$105,A16,Scenarios!$V$6:$V$105) -> 4.7564477e-06 | K16: =SUMIF(Scenarios!$E$6:$E$105,A16,Scenarios!$R$6:$R$105) -> 0
A17: T3S4 | B17: Low sun / hard shadow | C17: 75–95 km/h | D17: 1500 | E17: 0 | F17: =E17/D17 -> 0 | G17: =CHIINV(1-Inputs!$B$6,2*(E17+1))/2/D17 -> 0.0019971548 | H17: =CHIINV(1-Inputs!$B$10,2*(E17+1))/2/D17 -> 0.005188816 | I17: 0.0003 | J17: =SUMIF(Scenarios!$E$6:$E$105,A17,Scenarios!$V$6:$V$105) -> 3.1974227e-06 | K17: =SUMIF(Scenarios!$E$6:$E$105,A17,Scenarios!$R$6:$R$105) -> 0
... A25: T5S4 | B25: Roadside clutter / debris | C25: 75–95 km/h | D25: 1000 | E25: 2 | F25: =E25/D25 -> 0.002 | G25: =CHIINV(1-Inputs!$B$6,2*(E25+1))/2/D25 -> 0.0062957936 | H25: =CHIINV(1-Inputs!$B$10,2*(E25+1))/2/D25 -> 0.012266178 | I25: 0.00045 | J25: =SUMIF(Scenarios!$E$6:$E$105,A25,Scenarios!$V$6:$V$105) -> 8.9151066e-07 | K25: =SUMIF(Scenarios!$E$6:$E$105,A25,Scenarios!$R$6:$R$105) -> 5.5695345e-10
C27: Totals | D27: =SUM(D6:D25) -> 73500 | E27: =SUM(E6:E25) -> 14
A29: λ upper = ½·χ²_{2(k+1)}(C)/h — the lesson 1 formula, applied per cell. Zero events in h hours still gives a bound of ≈3/h at 95%.

Sheet Scenarios
A1: 100 logical scenarios
A2: One row per element of the ODD partition. Contribution = share · λ · P(collision|HB) · E[P(MAIS2+)|collision].
A5: ID | B5: Trigger context | C5: Speed band | D5: Follower headway | E5: Evidence cell | F5: Share trigger | G5: Share speed | H5: Share headway | I5: Scenario share | J5: λ̂ [1/h] | K5: λ upper (C_b) [1/h] | L5: Sim runs N | M5: Collisions c | N5: P̂(coll|HB) | O5: P upper (C_b) | P5: E[P(MAIS2+)|coll] | Q5: Mean Δv at contact [km/h] | R5: Point contribution [1/h] | S5: Upper contribution [1/h] | T5: Share of point risk | U5: Screening bound share·λ_U [1/h] | V5: Harm weight share·P_U·inj | W5: True λ (synthetic) [1/h] | X5: Contribution with true λ [1/h] | Y5: Σ w of 10 concrete | Z5: Effective sample size (Σw)²/Σw² | AA5: Collisions among 10 concrete | AB5: IS estimate E[coll·P(MAIS2+)] | AC5: IS point contribution [1/h]
A6: L001 | B6: Clear road, no trigger | C6: 20–35 km/h | D6: No follower within 3 s | E6: T1S1 | F6: =INDEX(Inputs!$B$15:$B$19,MATCH(B6,Inputs!$A$15:$A$19,0)) -> 0.8 | G6: =INDEX(Inputs!$B$23:$B$26,MATCH(C6,Inputs!$A$23:$A$26,0)) -> 0.35 | H6: =INDEX(Inputs!$B$30:$B$34,MATCH(D6,Inputs!$A$30:$A$34,0)) -> 0.45 | I6: =F6*G6*H6 -> 0.126 | J6: =INDEX('HB Evidence'!$F$6:$F$25,MATCH(E6,'HB Evidence'!$A$6:$A$25,0)) -> 0 | K6: =INDEX('HB Evidence'!$H$6:$H$25,MATCH(E6,'HB Evidence'!$A$6:$A$25,0)) -> 0.000648602 | L6: 2000 | M6: 0 | N6: =M6/L6 -> 0 | O6: =IF(M6=L6,1,BETAINV(Inputs!$B$10,M6+1,L6-M6)) -> 0.0038840495 | P6: 0 | Q6: 0 | R6: =I6*J6*N6*P6 -> 0 | S6: =I6*K6*O6*P6 -> 0 | T6: =IF(Summary!$B$6>0,R6/Summary!$B$6,0) -> 0 | U6: =I6*K6 -> 8.1723852e-05 | V6: =I6*O6*P6 -> 0 | W6: =INDEX('HB Evidence'!$I$6:$I$25,MATCH(E6,'HB Evidence'!$A$6:$A$25,0)) -> 2e-05 | X6: =I6*W6*N6*P6 -> 0 | Y6: =SUMIF('Concrete Scenarios'!$B$6:$B$1005,A6,'Concrete Scenarios'!$N$6:$N$1005) -> 6.1682947 | Z6: =IF(SUMIF('Concrete Scenarios'!$B$6:$B$1005,A6,'Concrete Scenarios'!$T$6:$T$1005)>0,Y6^2/SUMIF('Concrete Scenarios'!$B$6:$B$1005,A6,'Concrete Scenarios'!$T$6:$T$1005),0) -> 4.5000987 | AA6: =SUMIF('Concrete Scenarios'!$B$6:$B$1005,A6,'Concrete Scenarios'!$O$6:$O$1005) -> 0 | AB6: =SUMIF('Concrete Scenarios'!$B$6:$B$1005,A6,'Concrete Scenarios'!$S$6:$S$1005)/COUNTIF('Concrete Scenarios'!$B$6:$B$1005,A6) -> 0 | AC6: =I6*J6*AB6 -> 0
A7: L002 | B7: Clear road, no trigger | C7: 20–35 km/h | D7: Follower 2–3 s | E7: T1S1 | F7: =INDEX(Inputs!$B$15:$B$19,MATCH(B7,Inputs!$A$15:$A$19,0)) -> 0.8 | G7: =INDEX(Inputs!$B$23:$B$26,MATCH(C7,Inputs!$A$23:$A$26,0)) -> 0.35 | H7: =INDEX(Inputs!$B$30:$B$34,MATCH(D7,Inputs!$A$30:$A$34,0)) -> 0.2 | I7: =F7*G7*H7 -> 0.056 | J7: =INDEX('HB Evidence'!$F$6:$F$25,MATCH(E7,'HB Evidence'!$A$6:$A$25,0)) -> 0 | K7: =INDEX('HB Evidence'!$H$6:$H$25,MATCH(E7,'HB Evidence'!$A$6:$A$25,0)) -> 0.000648602 | L7: 2000 | M7: 1 | N7: =M7/L7 -> 0.0005 | O7: =IF(M7=L7,1,BETAINV(Inputs!$B$10,M7+1,L7-M7)) -> 0.0050878155 | P7: 0.0151 | Q7: 15.76 | R7: =I7*J7*N7*P7 -> 0 | S7: =I7*K7*O7*P7 -> 2.7904524e-09 | T7: =IF(Summary!$B$6>0,R7/Summary!$B$6,0) -> 0 | U7: =I7*K7 -> 3.6321712e-05 | V7: =I7*O7*P7 -> 4.3022568e-06 | W7: =INDEX('HB Evidence'!$I$6:$I$25,MATCH(E7,'HB Evidence'!$A$6:$A$25,0)) -> 2e-05 | X7: =I7*W7*N7*P7 -> 8.456e-12 | Y7: =SUMIF('Concrete Scenarios'!$B$6:$B$1005,A7,'Concrete Scenarios'!$N$6:$N$1005) -> 23.404669 | Z7: =IF(SUMIF('Concrete Scenarios'!$B$6:$B$1005,A7,'Concrete Scenarios'!$T$6:$T$1005)>0,Y7^2/SUMIF('Concrete Scenarios'!$B$6:$B$1005,A7,'Concrete Scenarios'!$T$6:$T$1005),0) -> 2.5164703 | AA7: =SUMIF('Concrete Scenarios'!$B$6:$B$1005,A7,'Concrete Scenarios'!$O$6:$O$1005) -> 0 | AB7: =SUMIF('Concrete Scenarios'!$B$6:$B$1005,A7,'Concrete Scenarios'!$S$6:$S$1005)/COUNTIF('Concrete Scenarios'!$B$6:$B$1005,A7) -> 0 | AC7: =I7*J7*AB7 -> 0
A8: L003 | B8: Clear road, no trigger | C8: 20–35 km/h | D8: Follower 1.5–2 s | E8: T1S1 | F8: =INDEX(Inputs!$B$15:$B$19,MATCH(B8,Inputs!$A$15:$A$19,0)) -> 0.8 | G8: =INDEX(Inputs!$B$23:$B$26,MATCH(C8,Inputs!$A$23:$A$26,0)) -> 0.35 | H8: =INDEX(Inputs!$B$30:$B$34,MATCH(D8,Inputs!$A$30:$A$34,0)) -> 0.15 | I8: =F8*G8*H8 -> 0.042 | J8: =INDEX('HB Evidence'!$F$6:$F$25,MATCH(E8,'HB Evidence'!$A$6:$A$25,0)) -> 0 | K8: =INDEX('HB Evidence'!$H$6:$H$25,MATCH(E8,'HB Evidence'!$A$6:$A$25,0)) -> 0.000648602 | L8: 2000 | M8: 30 | N8: =M8/L8 -> 0.015 | O8: =IF(M8=L8,1,BETAINV(Inputs!$B$10,M8+1,L8-M8)) -> 0.026370599 | P8: 0.011874 | Q8: 11.26 | R8: =I8*J8*N8*P8 -> 0 | S8: =I8*K8*O8*P8 -> 8.5299132e-09 | T8: =IF(Summary!$B$6>0,R8/Summary!$B$6,0) -> 0 | U8: =I8*K8 -> 2.7241284e-05 | V8: =I8*O8*P8 -> 1.3151229e-05 | W8: =INDEX('HB Evidence'!$I$6:$I$25,MATCH(E8,'HB Evidence'!$A$6:$A$25,0)) -> 2e-05 | X8: =I8*W8*N8*P8 -> 1.496124e-10 | Y8: =SUMIF('Concrete Scenarios'!$B$6:$B$1005,A8,'Concrete Scenarios'!$N$6:$N$1005) -> 7.6244733 | Z8: =IF(SUMIF('Concrete Scenarios'!$B$6:$B$1005,A8,'Concrete Scenarios'!$T$6:$T$1005)>0,Y8^2/SUMIF('Concrete Scenarios'!$B$6:$B$1005,A8,'Concrete Scenarios'!$T$6:$T$1005),0) -> 2.5018019 | AA8: =SUMIF('Concrete Scenarios'!$B$6:$B$1005,A8,'Concrete Scenarios'!$O$6:$O$1005) -> 3 | AB8: =SUMIF('Concrete Scenarios'!$B$6:$B$1005,A8,'Concrete Scenarios'!$S$6:$S$1005)/COUNTIF('Concrete Scenarios'!$B$6:$B$1005,A8) -> 0.00012296913 | AC8: =I8*J8*AB8 -> 0
A9: L004 | B9: Clear road, no trigger | C9: 20–35 km/h | D9: Follower 1–1.5 s | E9: T1S1 | F9: =INDEX(Inputs!$B$15:$B$19,MATCH(B9,Inputs!$A$15:$A$19,0)) -> 0.8 | G9: =INDEX(Inputs!$B$23:$B$26,MATCH(C9,Inputs!$A$23:$A$26,0)) -> 0.35 | H9: =INDEX(Inputs!$B$30:$B$34,MATCH(D9,Inputs!$A$30:$A$34,0)) -> 0.13 | I9: =F9*G9*H9 -> 0.0364 | J9: =INDEX('HB Evidence'!$F$6:$F$25,MATCH(E9,'HB Evidence'!$A$6:$A$25,0)) -> 0 | K9: =INDEX('HB Evidence'!$H$6:$H$25,MATCH(E9,'HB Evidence'!$A$6:$A$25,0)) -> 0.000648602 | L9: 2000 | M9: 121 | N9: =M9/L9 -> 0.0605 | O9: =IF(M9=L9,1,BETAINV(Inputs!$B$10,M9+1,L9-M9)) -> 0.080318059 | P9: 0.02077 | Q9: 15.01 | R9: =I9*J9*N9*P9 -> 0 | S9: =I9*K9*O9*P9 -> 3.9384866e-08 | T9: =IF(Summary!$B$6>0,R9/Summary!$B$6,0) -> 0 | U9: =I9*K9 -> 2.3609113e-05 | V9: =I9*O9*P9 -> 6.0722701e-05 | W9: =INDEX('HB Evidence'!$I$6:$I$25,MATCH(E9,'HB Evidence'!$A$6:$A$25,0)) -> 2e-05 | X9: =I9*W9*N9*P9 -> 9.1479388e-10 | Y9: =SUMIF('Concrete Scenarios'!$B$6:$B$1005,A9,'Concrete Scenarios'!$N$6:$N$1005) -> 5.1217355 | Z9: =IF(SUMIF('Concrete Scenarios'!$B$6:$B$1005,A9,'Concrete Scenarios'!$T$6:$T$1005)>0,Y9^2/SUMIF('Concrete Scenarios'!$B$6:$B$1005,A9,'Concrete Scenarios'!$T$6:$T$1005),0) -> 4.4481223 | AA9: =SUMIF('Concrete Scenarios'!$B$6:$B$1005,A9,'Concrete Scenarios'!$O$6:$O$1005) -> 3 | AB9: =SUMIF('Concrete Scenarios'!$B$6:$B$1005,A9,'Concrete Scenarios'!$S$6:$S$1005)/COUNTIF('Concrete Scenarios'!$B$6:$B$1005,A9) -> 0.00024339548 | AC9: =I9*J9*AB9 -> 0
A10: L005 | B10: Clear road, no trigger | C10: 20–35 km/h | D10: Follower < 1 s | E10: T1S1 | F10: =INDEX(Inputs!$B$15:$B$19,MATCH(B10,Inputs!$A$15:$A$19,0)) -> 0.8 | G10: =INDEX(Inputs!$B$23:$B$26,MATCH(C10,Inputs!$A$23:$A$26,0)) -> 0.35 | H10: =INDEX(Inputs!$B$30:$B$34,MATCH(D10,Inputs!$A$30:$A$34,0)) -> 0.07 | I10: =F10*G10*H10 -> 0.0196 | J10: =INDEX('HB Evidence'!$F$6:$F$25,MATCH(E10,'HB Evidence'!$A$6:$A$25,0)) -> 0 | K10: =INDEX('HB Evidence'!$H$6:$H$25,MATCH(E10,'HB Evidence'!$A$6:$A$25,0)) -> 0.000648602 | L10: 2000 | M10: 469 | N10: =M10/L10 -> 0.2345 | O10: =IF(M10=L10,1,BETAINV(Inputs!$B$10,M10+1,L10-M10)) -> 0.26740884 | P10: 0.019355 | Q10: 14.86 | R10: =I10*J10*N10*P10 -> 0 | S10: =I10*K10*O10*P10 -> 6.5796576e-08 | T10: =IF(Summary!$B$6>0,R10/Summary!$B$6,0) -> 0 | U10: =I10*K10 -> 1.2712599e-05 | V10: =I10*O10*P10 -> 0.00010144368 | W10: =INDEX('HB Evidence'!$I$6:$I$25,MATCH(E10,'HB Evidence'!$A$6:$A$25,0)) -> 2e-05 | X10: =I10*W10*N10*P10 -> 1.779189e-09 | Y10: =SUMIF('Concrete Scenarios'!$B$6:$B$1005,A10,'Concrete Scenarios'!$N$6:$N$1005) -> 8.3608173 | Z10: =IF(SUMIF('Concrete Scenarios'!$B$6:$B$1005,A10,'Concrete Scenarios'!$T$6:$T$1005)>0,Y10^2/SUMIF('Concrete Scenarios'!$B$6:$B$1005,A10,'Concrete Scenarios'!$T$6:$T$1005),0) -> 1.7892915 | AA10: =SUMIF('Concrete Scenarios'!$B$6:$B$1005,A10,'Concrete Scenarios'!$O$6:$O$1005) -> 6 | AB10: =SUMIF('Concrete Scenarios'!$B$6:$B$1005,A10,'Concrete Scenarios'!$S$6:$S$1005)/COUNTIF('Concrete Scenarios'!$B$6:$B$1005,A10) -> 0.0029745881 | AC10: =I10*J10*AB10 -> 0
A11: L006 | B11: Clear road, no trigger | C11: 35–55 km/h | D11: No follower within 3 s | E11: T1S2 | F11: =INDEX(Inputs!$B$15:$B$19,MATCH(B11,Inputs!$A$15:$A$19,0)) -> 0.8 | G11: =INDEX(Inputs!$B$23:$B$26,MATCH(C11,Inputs!$A$23:$A$26,0)) -> 0.4 | H11: =INDEX(Inputs!$B$30:$B$34,MATCH(D11,Inputs!$A$30:$A$34,0)) -> 0.45 | I11: =F11*G11*H11 -> 0.144 | J11: =INDEX('HB Evidence'!$F$6:$F$25,MATCH(E11,'HB Evidence'!$A$6:$A$25,0)) -> 0 | K11: =INDEX('HB Evidence'!$H$6:$H$25,MATCH(E11,'HB Evidence'!$A$6:$A$25,0)) -> 0.00055594457 | L11: 2000 | M11: 0 | N11: =M11/L11 -> 0 | O11: =IF(M11=L11,1,BETAINV(Inputs!$B$10,M11+1,L11-M11)) -> 0.0038840495 | P11: 0 | Q11: 0 | R11: =I11*J11*N11*P11 -> 0 | S11: =I11*K11*O11*P11 -> 0 | T11: =IF(Summary!$B$6>0,R11/Summary!$B$6,0) -> 0 | U11: =I11*K11 -> 8.0056018e-05 | V11: =I11*O11*P11 -> 0 | W11: =INDEX('HB Evidence'!$I$6:$I$25,MATCH(E11,'HB Evidence'!$A$6:$A$25,0)) -> 2e-05 | X11: =I11*W11*N11*P11 -> 0 | Y11: =SUMIF('Concrete Scenarios'!$B$6:$B$1005,A11,'Concrete Scenarios'!$N$6:$N$1005) -> 2.0443599 | Z11: =IF(SUMIF('Concrete Scenarios'!$B$6:$B$1005,A11,'Concrete Scenarios'!$T$6:$T$1005)>0,Y11^2/SUMIF('Concrete Scenarios'!$B$6:$B$1005,A11,'Concrete Scenarios'!$T$6:$T$1005),0) -> 5.9659171 | AA11: =SUMIF('Concrete Scenarios'!$B$6:$B$1005,A11,'Concrete Scenarios'!$O$6:$O$1005) -> 0 | AB11: =SUMIF('Concrete Scenarios'!$B$6:$B$1005,A11,'Concrete Scenarios'!$S$6:$S$1005)/COUNTIF('Concrete Scenarios'!$B$6:$B$1005,A11) -> 0 | AC11: =I11*J11*AB11 -> 0
A12: L007 | B12: Clear road, no trigger | C12: 35–55 km/h | D12: Follower 2–3 s | E12: T1S2 | F12: =INDEX(Inputs!$B$15:$B$19,MATCH(B12,Inputs!$A$15:$A$19,0)) -> 0.8 | G12: =INDEX(Inputs!$B$23:$B$26,MATCH(C12,Inputs!$A$23:$A$26,0)) -> 0.4 | H12: =INDEX(Inputs!$B$30:$B$34,MATCH(D12,Inputs!$A$30:$A$34,0)) -> 0.2 | I12: =F12*G12*H12 -> 0.064 | J12: =INDEX('HB Evidence'!$F$6:$F$25,MATCH(E12,'HB Evidence'!$A$6:$A$25,0)) -> 0 | K12: =INDEX('HB Evidence'!$H$6:$H$25,MATCH(E12,'HB Evidence'!$A$6:$A$25,0)) -> 0.00055594457 | L12: 2000 | M12: 1 | N12: =M12/L12 -> 0.0005 | O12: =IF(M12=L12,1,BETAINV(Inputs!$B$10,M12+1,L12-M12)) -> 0.0050878155 | P12: 0.070485 | Q12: 26.95 | R12: =I12*J12*N12*P12 -> 0 | S12: =I12*K12*O12*P12 -> 1.2759673e-08 | T12: =IF(Summary!$B$6>0,R12/Summary!$B$6,0) -> 0 | U12: =I12*K12 -> 3.5580453e-05 | V12: =I12*O12*P12 -> 2.2951339e-05 | W12: =INDEX('HB Evidence'!$I$6:$I$25,MATCH(E12,'HB Evidence'!$A$6:$A$25,0)) -> 2e-05 | X12: =I12*W12*N12*P12 -> 4.51104e-11 | Y12: =SUMIF('Concrete Scenarios'!$B$6:$B$1005,A12,'Concrete Scenarios'!$N$6:$N$1005) -> 4.5493788 | Z12: =IF(SUMIF('Concrete Scenarios'!$B$6:$B$1005,A12,'Concrete Scenarios'!$T$6:$T$1005)>0,Y12^2/SUMIF('Concrete Scenarios'!$B$6:$B$1005,A12,'Concrete Scenarios'!$T$6:$T$1005),0) -> 4.6517671 | AA12: =SUMIF('Concrete Scenarios'!$B$6:$B$1005,A12,'Concrete Scenarios'!$O$6:$O$1005) -> 0 | AB12: =SUMIF('Concrete Scenarios'!$B$6:$B$1005,A12,'Concrete Scenarios'!$S$6:$S$1005)/COUNTIF('Concrete Scenarios'!$B$6:$B$1005,A12) -> 0 | AC12: =I12*J12*AB12 -> 0
A13: L008 | B13: Clear road, no trigger | C13: 35–55 km/h | D13: Follower 1.5–2 s | E13: T1S2 | F13: =INDEX(Inputs!$B$15:$B$19,MATCH(B13,Inputs!$A$15:$A$19,0)) -> 0.8 | G13: =INDEX(Inputs!$B$23:$B$26,MATCH(C13,Inputs!$A$23:$A$26,0)) -> 0.4 | H13: =INDEX(Inputs!$B$30:$B$34,MATCH(D13,Inputs!$A$30:$A$34,0)) -> 0.15 | I13: =F13*G13*H13 -> 0.048 | J13: =INDEX('HB Evidence'!$F$6:$F$25,MATCH(E13,'HB Evidence'!$A$6:$A$25,0)) -> 0 | K13: =INDEX('HB Evidence'!$H$6:$H$25,MATCH(E13,'HB Evidence'!$A$6:$A$25,0)) -> 0.00055594457 | L13: 2000 | M13: 7 | N13: =M13/L13 -> 0.0035 | O13: =IF(M13=L13,1,BETAINV(Inputs!$B$10,M13+1,L13-M13)) -> 0.010423995 | P13: 0.035504 | Q13: 20.01 | R13: =I13*J13*N13*P13 -> 0 | S13: =I13*K13*O13*P13 -> 9.8760711e-09 | T13: =IF(Summary!$B$6>0,R13/Summary!$B$6,0) -> 0 | U13: =I13*K13 -> 2.6685339e-05 | V13: =I13*O13*P13 -> 1.7764489e-05 | W13: =INDEX('HB Evidence'!$I$6:$I$25,MATCH(E13,'HB Evidence'!$A$6:$A$25,0)) -> 2e-05 | X13: =I13*W13*N13*P13 -> 1.1929344e-10 | Y13: =SUMIF('Concrete Scenarios'!$B$6:$B$1005,A13,'Concrete Scenarios'!$N$6:$N$1005) -> 5.7231076 | Z13: =IF(SUMIF('Concrete Scenarios'!$B$6:$B$1005,A13,'Concrete Scenarios'!$T$6:$T$1005)>0,Y13^2/SUMIF('Concrete Scenarios'!$B$6:$B$1005,A13,'Concrete Scenarios'!$T$6:$T$1005),0) -> 3.3335805 | AA13: =SUMIF('Concrete Scenarios'!$B$6:$B$1005,A13,'Concrete Scenarios'!$O$6:$O$1005) -> 1 | AB13: =SUMIF('Concrete Scenarios'!$B$6:$B$1005,A13,'Concrete Scenarios'!$S$6:$S$1005)/COUNTIF('Concrete Scenarios'!$B$6:$B$1005,A13) -> 0.00015680466 | AC13: =I13*J13*AB13 -> 0
A14: L009 | B14: Clear road, no trigger | C14: 35–55 km/h | D14: Follower 1–1.5 s | E14: T1S2 | F14: =INDEX(Inputs!$B$15:$B$19,MATCH(B14,Inputs!$A$15:$A$19,0)) -> 0.8 | G14: =INDEX(Inputs!$B$23:$B$26,MATCH(C14,Inputs!$A$23:$A$26,0)) -> 0.4 | H14: =INDEX(Inputs!$B$30:$B$34,MATCH(D14,Inputs!$A$30:$A$34,0)) -> 0.13 | I14: =F14*G14*H14 -> 0.0416 | J14: =INDEX('HB Evidence'!$F$6:$F$25,MATCH(E14,'HB Evidence'!$A$6:$A$25,0)) -> 0 | K14: =INDEX('HB Evidence'!$H$6:$H$25,MATCH(E14,'HB Evidence'!$A$6:$A$25,0)) -> 0.00055594457 | L14: 2000 | M14: 29 | N14: =M14/L14 -> 0.0145 | O14: =IF(M14=L14,1,BETAINV(Inputs!$B$10,M14+1,L14-M14)) -> 0.02572537 | P14: 0.047174 | Q14: 18.98 | R14: =I14*J14*N14*P14 -> 0 | S14: =I14*K14*O14*P14 -> 2.8066558e-08 | T14: =IF(Summary!$B$6>0,R14/Summary!$B$6,0) -> 0 | U14: =I14*K14 -> 2.3127294e-05 | V14: =I14*O14*P14 -> 5.0484454e-05 | W14: =INDEX('HB Evidence'!$I$6:$I$25,MATCH(E14,'HB Evidence'!$A$6:$A$25,0)) -> 2e-05 | X14: =I14*W14*N14*P14 -> 5.6910714e-10 | Y14: =SUMIF('Concrete Scenarios'!$B$6:$B$1005,A14,'Concrete Scenarios'!$N$6:$N$1005) -> 5.7842855 | Z14: =IF(SUMIF('Concrete Scenarios'!$B$6:$B$1005,A14,'Concrete Scenarios'!$T$6:$T$1005)>0,Y14^2/SUMIF('Concrete Scenarios'!$B$6:$B$1005,A14,'Concrete Scenarios'!$T$6:$T$1005),0) -> 3.6256565 | AA14: =SUMIF('Concrete Scenarios'!$B$6:$B$1005,A14,'Concrete Scenarios'!$O$6:$O$1005) -> 0 | AB14: =SUMIF('Concrete Scenarios'!$B$6:$B$1005,A14,'Concrete Scenarios'!$S$6:$S$1005)/COUNTIF('Concrete Scenarios'!$B$6:$B$1005,A14) -> 0 | AC14: =I14*J14*AB14 -> 0
A15: L010 | B15: Clear road, no trigger | C15: 35–55 km/h | D15: Follower < 1 s | E15: T1S2 | F15: =INDEX(Inputs!$B$15:$B$19,MATCH(B15,Inputs!$A$15:$A$19,0)) -> 0.8 | G15: =INDEX(Inputs!$B$23:$B$26,MATCH(C15,Inputs!$A$23:$A$26,0)) -> 0.4 | H15: =INDEX(Inputs!$B$30:$B$34,MATCH(D15,Inputs!$A$30:$A$34,0)) -> 0.07 | I15: =F15*G15*H15 -> 0.0224 | J15: =INDEX('HB Evidence'!$F$6:$F$25,MATCH(E15,'HB Evidence'!$A$6:$A$25,0)) -> 0 | K15: =INDEX('HB Evidence'!$H$6:$H$25,MATCH(E15,'HB Evidence'!$A$6:$A$25,0)) -> 0.00055594457 | L15: 2000 | M15: 179 | N15: =M15/L15 -> 0.0895 | O15: =IF(M15=L15,1,BETAINV(Inputs!$B$10,M15+1,L15-M15)) -> 0.11269706 | P15: 0.036636 | Q15: 17.86 | R15: =I15*J15*N15*P15 -> 0 | S15: =I15*K15*O15*P15 -> 5.1416221e-08 | T15: =IF(Summary!$B$6>0,R15/Summary!$B$6,0) -> 0 | U15: =I15*K15 -> 1.2453158e-05 | V15: =I15*O15*P15 -> 9.2484437e-05 | W15: =INDEX('HB Evidence'!$I$6:$I$25,MATCH(E15,'HB Evidence'!$A$6:$A$25,0)) -> 2e-05 | X15: =I15*W15*N15*P15 -> 1.4689571e-09 | Y15: =SUMIF('Concrete Scenarios'!$B$6:$B$1005,A15,'Concrete Scenarios'!$N$6:$N$1005) -> 7.1859159 | Z15: =IF(SUMIF('Concrete Scenarios'!$B$6:$B$1005,A15,'Concrete Scenarios'!$T$6:$T$1005)>0,Y15^2/SUMIF('Concrete Scenarios'!$B$6:$B$1005,A15,'Concrete Scenarios'!$T$6:$T$1005),0) -> 3.37632 | AA15: =SUMIF('Concrete Scenarios'!$B$6:$B$1005,A15,'Concrete Scenarios'!$O$6:$O$1005) -> 6 | AB15: =SUMIF('Concrete Scenarios'!$B$6:$B$1005,A15,'Concrete Scenarios'!$S$6:$S$1005)/COUNTIF('Concrete Scenarios'!$B$6:$B$1005,A15) -> 0.0044213966 | AC15: =I15*J15*AB15 -> 0
A16: L011 | B16: Clear road, no trigger | C16: 55–75 km/h | D16: No follower within 3 s | E16: T1S3 | F16: =INDEX(Inputs!$B$15:$B$19,MATCH(B16,Inputs!$A$15:$A$19,0)) -> 0.8 | G16: =INDEX(Inputs!$B$23:$B$26,MATCH(C16,Inputs!$A$23:$A$26,0)) -> 0.15 | H16: =INDEX(Inputs!$B$30:$B$34,MATCH(D16,Inputs!$A$30:$A$34,0)) -> 0.45 | I16: =F16*G16*H16 -> 0.054 | J16: =INDEX('HB Evidence'!$F$6:$F$25,MATCH(E16,'HB Evidence'!$A$6:$A$25,0)) -> 0 | K16: =INDEX('HB Evidence'!$H$6:$H$25,MATCH(E16,'HB Evidence'!$A$6:$A$25,0)) -> 0.001297204 | L16: 2000 | M16: 0 | N16: =M16/L16 -> 0 | O16: =IF(M16=L16,1,BETAINV(Inputs!$B$10,M16+1,L16-M16)) -> 0.0038840495 | P16: 0 | Q16: 0 | R16: =I16*J16*N16*P16 -> 0 | S16: =I16*K16*O16*P16 -> 0 | T16: =IF(Summary!$B$6>0,R16/Summary!$B$6,0) -> 0 | U16: =I16*K16 -> 7.0049016e-05 | V16: =I16*O16*P16 -> 0 | W16: =INDEX('HB Evidence'!$I$6:$I$25,MATCH(E16,'HB Evidence'!$A$6:$A$25,0)) -> 2.4e-05 | X16: =I16*W16*N16*P16 -> 0 | Y16: =SUMIF('Concrete Scenarios'!$B$6:$B$1005,A16,'Concrete Scenarios'!$N$6:$N$1005) -> 8.5054874 | Z16: =IF(SUMIF('Concrete Scenarios'!$B$6:$B$1005,A16,'Concrete Scenarios'!$T$6:$T$1005)>0,Y16^2/SUMIF('Concrete Scenarios'!$B$6:$B$1005,A16,'Concrete Scenarios'!$T$6:$T$1005),0) -> 2.1804068 | AA16: =SUMIF('Concrete Scenarios'!$B$6:$B$1005,A16,'Concrete Scenarios'!$O$6:$O$1005) -> 0 | AB16: =SUMIF('Concrete Scenarios'!$B$6:$B$1005,A16,'Concrete Scenarios'!$S$6:$S$1005)/COUNTIF('Concrete Scenarios'!$B$6:$B$1005,A16) -> 0 | AC16: =I16*J16*AB16 -> 0
A17: L012 | B17: Clear road, no trigger | C17: 55–75 km/h | D17: Follower 2–3 s | E17: T1S3 | F17: =INDEX(Inputs!$B$15:$B$19,MATCH(B17,Inputs!$A$15:$A$19,0)) -> 0.8 | G17: =INDEX(Inputs!$B$23:$B$26,MATCH(C17,Inputs!$A$23:$A$26,0)) -> 0.15 | H17: =INDEX(Inputs!$B$30:$B$34,MATCH(D17,Inputs!$A$30:$A$34,0)) -> 0.2 | I17: =F17*G17*H17 -> 0.024 | J17: =INDEX('HB Evidence'!$F$6:$F$25,MATCH(E17,'HB Evidence'!$A$6:$A$25,0)) -> 0 | K17: =INDEX('HB Evidence'!$H$6:$H$25,MATCH(E17,'HB Evidence'!$A$6:$A$25,0)) -> 0.001297204 | L17: 2000 | M17: 0 | N17: =M17/L17 -> 0 | O17: =IF(M17=L17,1,BETAINV(Inputs!$B$10,M17+1,L17-M17)) -> 0.0038840495 | P17: 0 | Q17: 0 | R17: =I17*J17*N17*P17 -> 0 | S17: =I17*K17*O17*P17 -> 0 | T17: =IF(Summary!$B$6>0,R17/Summary!$B$6,0) -> 0 | U17: =I17*K17 -> 3.1132896e-05 | V17: =I17*O17*P17 -> 0 | W17: =INDEX('HB Evidence'!$I$6:$I$25,MATCH(E17,'HB Evidence'!$A$6:$A$25,0)) -> 2.4e-05 | X17: =I17*W17*N17*P17 -> 0 | Y17: =SUMIF('Concrete Scenarios'!$B$6:$B$1005,A17,'Concrete Scenarios'!$N$6:$N$1005) -> 5.4454846 | Z17: =IF(SUMIF('Concrete Scenarios'!$B$6:$B$1005,A17,'Concrete Scenarios'!$T$6:$T$1005)>0,Y17^2/SUMIF('Concrete Scenarios'!$B$6:$B$1005,A17,'Concrete Scenarios'!$T$6:$T$1005),0) -> 4.9328461 | AA17: =SUMIF('Concrete Scenarios'!$B$6:$B$1005,A17,'Concrete Scenarios'!$O$6:$O$1005) -> 1 | AB17: =SUMIF('Concrete Scenarios'!$B$6:$B$1005,A17,'Concrete Scenarios'!$S$6:$S$1005)/COUNTIF('Concrete Scenarios'!$B$6:$B$1005,A17) -> 5.8906975e-05 | AC17: =I17*J17*AB17 -> 0
... A105: L100 | B105: Roadside clutter / debris | C105: 75–95 km/h | D105: Follower < 1 s | E105: T5S4 | F105: =INDEX(Inputs!$B$15:$B$19,MATCH(B105,Inputs!$A$15:$A$19,0)) -> 0.03 | G105: =INDEX(Inputs!$B$23:$B$26,MATCH(C105,Inputs!$A$23:$A$26,0)) -> 0.1 | H105: =INDEX(Inputs!$B$30:$B$34,MATCH(D105,Inputs!$A$30:$A$34,0)) -> 0.07 | I105: =F105*G105*H105 -> 0.00021 | J105: =INDEX('HB Evidence'!$F$6:$F$25,MATCH(E105,'HB Evidence'!$A$6:$A$25,0)) -> 0.002 | K105: =INDEX('HB Evidence'!$H$6:$H$25,MATCH(E105,'HB Evidence'!$A$6:$A$25,0)) -> 0.012266178 | L105: 2000 | M105: 27 | N105: =M105/L105 -> 0.0135 | O105: =IF(M105=L105,1,BETAINV(Inputs!$B$10,M105+1,L105-M105)) -> 0.02442703 | P105: 0.066489 | Q105: 21.87 | R105: =I105*J105*N105*P105 -> 3.7699263e-10 | S105: =I105*K105*O105*P105 -> 4.1835894e-09 | T105: =IF(Summary!$B$6>0,R105/Summary!$B$6,0) -> 0.018233306 | U105: =I105*K105 -> 2.5758975e-06 | V105: =I105*O105*P105 -> 3.4106705e-07 | W105: =INDEX('HB Evidence'!$I$6:$I$25,MATCH(E105,'HB Evidence'!$A$6:$A$25,0)) -> 0.00045 | X105: =I105*W105*N105*P105 -> 8.4823342e-11 | Y105: =SUMIF('Concrete Scenarios'!$B$6:$B$1005,A105,'Concrete Scenarios'!$N$6:$N$1005) -> 6.9093571 | Z105: =IF(SUMIF('Concrete Scenarios'!$B$6:$B$1005,A105,'Concrete Scenarios'!$T$6:$T$1005)>0,Y105^2/SUMIF('Concrete Scenarios'!$B$6:$B$1005,A105,'Concrete Scenarios'!$T$6:$T$1005),0) -> 4.0456521 | AA105: =SUMIF('Concrete Scenarios'!$B$6:$B$1005,A105,'Concrete Scenarios'!$O$6:$O$1005) -> 3 | AB105: =SUMIF('Concrete Scenarios'!$B$6:$B$1005,A105,'Concrete Scenarios'!$S$6:$S$1005)/COUNTIF('Concrete Scenarios'!$B$6:$B$1005,A105) -> 0.0012435322 | AC105: =I105*J105*AB105 -> 5.222835e-10
A107: Clopper–Pearson upper bound: P_U = BETAINV(C_b; c+1; N−c). With c = 0 and N = 2000 this is ≈ 7.8/2000 at C_b — the rule of three again, with a Bonferroni-sized confidence.

Sheet Concrete Scenarios
A1: 1,000 concrete scenarios (made up) — 10 per logical scenario
A2: Parameters drawn from the importance-sampling proposal q via the Gaussian copula; w = f(θ)/q(θ) re-weights each run to the real-world model f.
A5: Concrete ID | B5: Logical ID | C5: Trigger context | D5: Speed band | E5: Follower headway | F5: Ego speed v_e [km/h] | G5: Follower speed v_f [km/h] | H5: Time headway h [s] | I5: Gap [m] | J5: Phantom decel a_e [m/s²] | K5: Phantom duration t_b [s] | L5: Follower reaction T_r [s] | M5: Follower decel a_f [m/s²] | N5: IS weight w = f/q | O5: Collision (1/0) | P5: Δv at contact [km/h] | Q5: P(MAIS2+ | Δv) | R5: w · collision | S5: w · collision · P(MAIS2+) | T5: w²
A6: C0001 | B6: L001 | C6: Clear road, no trigger | D6: 20–35 km/h | E6: No follower within 3 s | F6: 20 | G6: 19.04 | H6: 3.131 | I6: =H6*G6/3.6 -> 16.559511 | J6: 2.56 | K6: 1.127 | L6: 1.223 | M6: 6.94 | N6: 0.69724254 | O6: 0 | P6: 0 | Q6: =IF(O6=1,1/(1+EXP(-(P6-Inputs!$B$12)/Inputs!$B$13)),0) -> 0 | R6: =N6*O6 -> 0 | S6: =N6*Q6 -> 0 | T6: =N6^2 -> 0.48614716
A7: C0002 | B7: L001 | C7: Clear road, no trigger | D7: 20–35 km/h | E7: No follower within 3 s | F7: 28.04 | G7: 27.17 | H7: 3.567 | I7: =H7*G7/3.6 -> 26.920942 | J7: 4.94 | K7: 1.296 | L7: 1.426 | M7: 6.34 | N7: 0.31719647 | O7: 0 | P7: 0 | Q7: =IF(O7=1,1/(1+EXP(-(P7-Inputs!$B$12)/Inputs!$B$13)),0) -> 0 | R7: =N7*O7 -> 0 | S7: =N7*Q7 -> 0 | T7: =N7^2 -> 0.1006136
A8: C0003 | B8: L001 | C8: Clear road, no trigger | D8: 20–35 km/h | E8: No follower within 3 s | F8: 21.44 | G8: 19.65 | H8: 3.565 | I8: =H8*G8/3.6 -> 19.458958 | J8: 2.69 | K8: 0.694 | L8: 1.327 | M8: 6.01 | N8: 1.583806 | O8: 0 | P8: 0 | Q8: =IF(O8=1,1/(1+EXP(-(P8-Inputs!$B$12)/Inputs!$B$13)),0) -> 0 | R8: =N8*O8 -> 0 | S8: =N8*Q8 -> 0 | T8: =N8^2 -> 2.5084414
A9: C0004 | B9: L001 | C9: Clear road, no trigger | D9: 20–35 km/h | E9: No follower within 3 s | F9: 33.74 | G9: 31.83 | H9: 5.628 | I9: =H9*G9/3.6 -> 49.7609 | J9: 3.61 | K9: 2.193 | L9: 1.31 | M9: 7.64 | N9: 0.32123979 | O9: 0 | P9: 0 | Q9: =IF(O9=1,1/(1+EXP(-(P9-Inputs!$B$12)/Inputs!$B$13)),0) -> 0 | R9: =N9*O9 -> 0 | S9: =N9*Q9 -> 0 | T9: =N9^2 -> 0.103195
A10: C0005 | B10: L001 | C10: Clear road, no trigger | D10: 20–35 km/h | E10: No follower within 3 s | F10: 21.99 | G10: 22.57 | H10: 3.313 | I10: =H10*G10/3.6 -> 20.770669 | J10: 5.81 | K10: 1.103 | L10: 1.663 | M10: 5.78 | N10: 0.28666775 | O10: 0 | P10: 0 | Q10: =IF(O10=1,1/(1+EXP(-(P10-Inputs!$B$12)/Inputs!$B$13)),0) -> 0 | R10: =N10*O10 -> 0 | S10: =N10*Q10 -> 0 | T10: =N10^2 -> 0.082178397
A11: C0006 | B11: L001 | C11: Clear road, no trigger | D11: 20–35 km/h | E11: No follower within 3 s | F11: 31.43 | G11: 32.11 | H11: 4.427 | I11: =H11*G11/3.6 -> 39.486381 | J11: 4.55 | K11: 2.326 | L11: 1.951 | M11: 3.76 | N11: 0.079087047 | O11: 0 | P11: 0 | Q11: =IF(O11=1,1/(1+EXP(-(P11-Inputs!$B$12)/Inputs!$B$13)),0) -> 0 | R11: =N11*O11 -> 0 | S11: =N11*Q11 -> 0 | T11: =N11^2 -> 0.0062547611
A12: C0007 | B12: L001 | C12: Clear road, no trigger | D12: 20–35 km/h | E12: No follower within 3 s | F12: 34.06 | G12: 34.32 | H12: 4.973 | I12: =H12*G12/3.6 -> 47.409267 | J12: 2.77 | K12: 1.161 | L12: 0.843 | M12: 5.57 | N12: 2.2386809 | O12: 0 | P12: 0 | Q12: =IF(O12=1,1/(1+EXP(-(P12-Inputs!$B$12)/Inputs!$B$13)),0) -> 0 | R12: =N12*O12 -> 0 | S12: =N12*Q12 -> 0 | T12: =N12^2 -> 5.011692
A13: C0008 | B13: L001 | C13: Clear road, no trigger | D13: 20–35 km/h | E13: No follower within 3 s | F13: 23.26 | G13: 23.64 | H13: 3.677 | I13: =H13*G13/3.6 -> 24.145633 | J13: 4.18 | K13: 2.83 | L13: 1.088 | M13: 6.03 | N13: 0.18654241 | O13: 0 | P13: 0 | Q13: =IF(O13=1,1/(1+EXP(-(P13-Inputs!$B$12)/Inputs!$B$13)),0) -> 0 | R13: =N13*O13 -> 0 | S13: =N13*Q13 -> 0 | T13: =N13^2 -> 0.03479807
A14: C0009 | B14: L001 | C14: Clear road, no trigger | D14: 20–35 km/h | E14: No follower within 3 s | F14: 31.92 | G14: 30.59 | H14: 3.654 | I14: =H14*G14/3.6 -> 31.04885 | J14: 4.35 | K14: 2.015 | L14: 1.396 | M14: 3.81 | N14: 0.320483 | O14: 0 | P14: 0 | Q14: =IF(O14=1,1/(1+EXP(-(P14-Inputs!$B$12)/Inputs!$B$13)),0) -> 0 | R14: =N14*O14 -> 0 | S14: =N14*Q14 -> 0 | T14: =N14^2 -> 0.10270935
A15: C0010 | B15: L001 | C15: Clear road, no trigger | D15: 20–35 km/h | E15: No follower within 3 s | F15: 34.51 | G15: 36.7 | H15: 3.985 | I15: =H15*G15/3.6 -> 40.624861 | J15: 4 | K15: 1.902 | L15: 1.606 | M15: 4.75 | N15: 0.13734886 | O15: 0 | P15: 0 | Q15: =IF(O15=1,1/(1+EXP(-(P15-Inputs!$B$12)/Inputs!$B$13)),0) -> 0 | R15: =N15*O15 -> 0 | S15: =N15*Q15 -> 0 | T15: =N15^2 -> 0.018864709
A16: C0011 | B16: L002 | C16: Clear road, no trigger | D16: 20–35 km/h | E16: Follower 2–3 s | F16: 28.01 | G16: 27.03 | H16: 2.281 | I16: =H16*G16/3.6 -> 17.126508 | J16: 5.96 | K16: 1.008 | L16: 1.018 | M16: 7.48 | N16: 1.0783534 | O16: 0 | P16: 0 | Q16: =IF(O16=1,1/(1+EXP(-(P16-Inputs!$B$12)/Inputs!$B$13)),0) -> 0 | R16: =N16*O16 -> 0 | S16: =N16*Q16 -> 0 | T16: =N16^2 -> 1.162846
A17: C0012 | B17: L002 | C17: Clear road, no trigger | D17: 20–35 km/h | E17: Follower 2–3 s | F17: 20.08 | G17: 18.37 | H17: 2.534 | I17: =H17*G17/3.6 -> 12.930439 | J17: 4.15 | K17: 1.242 | L17: 1.581 | M17: 7.59 | N17: 0.24369713 | O17: 0 | P17: 0 | Q17: =IF(O17=1,1/(1+EXP(-(P17-Inputs!$B$12)/Inputs!$B$13)),0) -> 0 | R17: =N17*O17 -> 0 | S17: =N17*Q17 -> 0 | T17: =N17^2 -> 0.059388292
... A1005: C1000 | B1005: L100 | C1005: Roadside clutter / debris | D1005: 75–95 km/h | E1005: Follower < 1 s | F1005: 85.77 | G1005: 85.73 | H1005: 0.647 | I1005: =H1005*G1005/3.6 -> 15.407586 | J1005: 5.58 | K1005: 0.789 | L1005: 1.64 | M1005: 5.95 | N1005: 0.54026979 | O1005: 0 | P1005: 0 | Q1005: =IF(O1005=1,1/(1+EXP(-(P1005-Inputs!$B$12)/Inputs!$B$13)),0) -> 0 | R1005: =N1005*O1005 -> 0 | S1005: =N1005*Q1005 -> 0 | T1005: =N1005^2 -> 0.29189144
A1007: Totals | N1007: =SUM(N6:N1005) -> 978.76011 | O1007: =SUM(O6:O1005) -> 117
A1008: Check: mean weight should be ≈ 1 (E_q[w] = 1). Strong deviations mean the proposal misses part of f's support. | N1008: =AVERAGE(N6:N1005) -> 0.97876011

Sheet Gaussian Copula
A1: Gaussian copula — how the scenario parameters are coupled
A2: Explanation, live correlation matrix and Cholesky factor, a live 200-sample demo, and the effect on P(collision | HB).
A4: What it is | B4: A copula is a joint distribution on [0,1]^d with uniform marginals. Sklar's theorem: any joint CDF can be written F(x₁…x_d) = C(F₁(x₁),…,F_d(x_d)). The Gaussian copula is C_R(u) = Φ_R(Φ⁻¹(u₁),…,Φ⁻¹(u_d)), with Φ_R the multivariate normal CDF with correlation matrix R.
A5: Why for scenarios | B5: Each scenario parameter has its own natural marginal (uniform speed within a band, lognormal reaction time, uniform deceleration…), but parameters are not independent. The copula separates the two questions: which values does each parameter take (marginals) and how do they move together (R).
A6: Sampling (3 steps) | B6: 1) ε ~ N(0, I), Z = L·ε with R = L·Lᵀ (Cholesky). 2) U_i = Φ(Z_i) — now uniform on [0,1] but correlated. 3) X_i = F_i⁻¹(U_i) — apply each marginal's inverse CDF. Live demo below (rows 66+).
A7: Density (needed for IS weights) | B7: c_R(u) = |R|^(−½) · exp(−½ zᵀ(R⁻¹ − I)z), z = Φ⁻¹(u). Joint density f(x) = c_R(F(x)) · Π f_i(x_i). The concrete-scenario weights w = f(θ)/q(θ) use this formula for both f and the proposal q.
A8: Fitting R from data | B8: Transform each parameter to pseudo-observations u = rank/(n+1), then z = Φ⁻¹(u); R = correlation matrix of z (normal scores). Alternative per pair: estimate Kendall's τ and use ρ = sin(πτ/2) (row 33). Rank-based fits are invariant to the marginals.
A9: Validity check | B9: R must be symmetric positive definite: det(R) > 0 and the Cholesky factor exists (all diagonal entries of L real and > 0). Pairwise-estimated correlations can violate this — then project to the nearest correlation matrix.
A10: Main limitation | B10: Zero tail dependence: joint extremes (very late reaction AND very weak braking) become asymptotically independent. If real data show joint extremes more often, the Gaussian copula under-estimates exactly the critical corner. Check with tail-dependence plots; use a t-copula (symmetric tail dependence) or vine copulas (flexible pairwise structure in high dimension).
A11: In this example | B11: R below is ILLUSTRATIVE, not measured. It couples ego speed, follower time headway, follower reaction time and follower deceleration; phantom-brake decel/duration and follower speed offset are independent. The Python simulation used the R values at build time; editing R here drives only the live demo and its correlation check.
A19: Correlation matrix R (edit the yellow upper triangle)
B20: v_e | C20: h | D20: T_r | E20: a_f
A21: v_e — Ego speed v_e | B21: 1 | C21: 0.25 | D21: 0 | E21: 0 | G21: det(R) | H21: =MDETERM(B21:E24) -> 0.6975
A22: h — Follower time headway h | B22: =C21 -> 0.25 | C22: 1 | D22: -0.3 | E22: 0 | G22: Valid? | H22: =IF(AND(H21>0,ISNUMBER(E30)),"positive definite","NOT positive definite") -> positive definite
A23: T_r — Follower reaction time T_r | B23: =D21 -> 0 | C23: =D22 -> -0.3 | D23: 1 | E23: -0.4
A24: a_f — Follower deceleration a_f | B24: =E21 -> 0 | C24: =E22 -> 0 | D24: =E23 -> -0.4 | E24: 1
A26: Cholesky factor L (R = L·Lᵀ), formulas | B26: v_e | C26: h | D26: T_r | E26: a_f
A27: v_e | B27: =SQRT(B21) -> 1 | C27: =0 -> 0 | D27: =0 -> 0 | E27: =0 -> 0
A28: h | B28: =B22/B27 -> 0.25 | C28: =SQRT(C22-B28^2) -> 0.96824584 | D28: =0 -> 0 | E28: =0 -> 0
A29: T_r | B29: =B23/B27 -> 0 | C29: =(C23-B29*B28)/C28 -> -0.30983867 | D29: =SQRT(D23-B29^2-C29^2) -> 0.95078915 | E29: =0 -> 0
A30: a_f | B30: =B24/B27 -> 0 | C30: =(C24-B30*B28)/C28 -> 0 | D30: =(D24-B30*B29-C30*C29)/D29 -> -0.42070316 | E30: =SQRT(E24-B30^2-C30^2-D30^2) -> 0.90719835
A32: Kendall τ → Gaussian-copula ρ
A33: Kendall τ (example) | B33: -0.2 | C33: ρ = sin(π·τ/2) = | E33: =SIN(PI()*B33/2) -> -0.30901699
A35: Effect of the copula on P(collision | HB) — 20,000 runs each (ub_sim.copula_effect)
A36: Speed band | B36: Follower headway | C36: P(coll|HB), Gaussian copula | D36: P(coll|HB), independent | E36: Ratio copula / independent | F36: Runs each
A37: 20–35 km/h | B37: No follower within 3 s | C37: 0 | D37: 0 | E37: =IF(D37>0,C37/D37,"–") -> – | F37: 20000
A38: 20–35 km/h | B38: Follower 2–3 s | C38: 0.0018 | D38: 0.00085 | E38: =IF(D38>0,C38/D38,"–") -> 2.1176471 | F38: 20000
A39: 20–35 km/h | B39: Follower 1.5–2 s | C39: 0.0131 | D39: 0.01005 | E39: =IF(D39>0,C39/D39,"–") -> 1.3034826 | F39: 20000
A40: 20–35 km/h | B40: Follower 1–1.5 s | C40: 0.0624 | D40: 0.052 | E40: =IF(D40>0,C40/D40,"–") -> 1.2 | F40: 20000
A41: 20–35 km/h | B41: Follower < 1 s | C41: 0.2375 | D41: 0.22475 | E41: =IF(D41>0,C41/D41,"–") -> 1.0567297 | F41: 20000
A42: 35–55 km/h | B42: No follower within 3 s | C42: 0 | D42: 0 | E42: =IF(D42>0,C42/D42,"–") -> – | F42: 20000
A43: 35–55 km/h | B43: Follower 2–3 s | C43: 0.0006 | D43: 0.00025 | E43: =IF(D43>0,C43/D43,"–") -> 2.4 | F43: 20000
A44: 35–55 km/h | B44: Follower 1.5–2 s | C44: 0.00345 | D44: 0.0022 | E44: =IF(D44>0,C44/D44,"–") -> 1.5681818 | F44: 20000
A45: 35–55 km/h | B45: Follower 1–1.5 s | C45: 0.01665 | D45: 0.01135 | E45: =IF(D45>0,C45/D45,"–") -> 1.4669604 | F45: 20000
A46: 35–55 km/h | B46: Follower < 1 s | C46: 0.08875 | D46: 0.0749 | E46: =IF(D46>0,C46/D46,"–") -> 1.1849132 | F46: 20000
A47: 55–75 km/h | B47: No follower within 3 s | C47: 0 | D47: 0 | E47: =IF(D47>0,C47/D47,"–") -> – | F47: 20000
A48: 55–75 km/h | B48: Follower 2–3 s | C48: 0.00015 | D48: 5e-05 | E48: =IF(D48>0,C48/D48,"–") -> 3 | F48: 20000
... A56: 75–95 km/h | B56: Follower < 1 s | C56: 0.012 | D56: 0.00985 | E56: =IF(D56>0,C56/D56,"–") -> 1.2182741 | F56: 20000
A58: Reading: with these signs, close followers react faster (h–T_r < 0) but slow reactors also brake weakly (T_r–a_f < 0). Ignoring dependence changes P(collision) by the factor in column E — an error that goes straight into the risk sum.
A60: Live sampling demo — logical scenario parameters (edit yellow)
...

Sheet Summary
A1: Summary — does the validation target hold?
A2: All values recalculate from Inputs, HB Evidence and Scenarios.
A4: Quantity | B4: Value | C4: Unit | D4: Verdict / note
A5: Scenario shares sum (partition check) | B5: =SUM(Scenarios!I6:I105) -> 1 | C5: - | D5: Must be 100%: logical scenarios are mutually exclusive and exhaustive within the ODD.
A6: Point estimate R̂ | B6: =SUM(Scenarios!R6:R105) -> 2.0676044e-08 | C6: 1/h | D6: Not evidence by itself — no confidence.
A7: Bonferroni upper bound R_U | B7: =SUM(Scenarios!S6:S105) -> 7.3460764e-07 | C7: 1/h | D7: All 120 estimated terms bounded simultaneously at C_b; products of upper bounds → conservative.
A8: Bayesian posterior 95% quantile | B8: 7.3188917e-08 | C8: 1/h | D8: From ub_sim.py: 200,000 posterior draws, Gamma(k+½, h) for λ, Beta(c+½, N−c+½) for P(coll). Value, not formula.
A9: Bayesian posterior mean | B9: 4.6613761e-08 | C9: 1/h | D9: From ub_sim.py.
A10: Acceptance criterion A_H | B10: =Inputs!B5 -> 1e-07 | C10: 1/h
A11: Budget for known scenarios (1−ε)·A_H | B11: =Inputs!B11 -> 9e-08 | C11: 1/h | D11: The remaining ε·A_H is reserved for unknown triggers (row 21).
A13: Verdicts against the known-scenario budget
A14: Point estimate | B14: =B6/B11 -> 0.22973382 | D14: =IF(B6<=B11,"meets budget (point only — not a valid claim)","exceeds budget") -> meets budget (point only — not a valid claim)
A15: Bonferroni upper bound | B15: =B7/B11 -> 8.1623071 | D15: =IF(B7<=B11,"PASS at confidence C","FAIL — evidence insufficient, see Validation Targets") -> FAIL — evidence insufficient, see Validation Targets
A16: Bayesian 95% quantile | B16: =B8/B11 -> 0.81321019 | D16: =IF(B8<=B11,"PASS at 95% posterior (prior must be justified to the assessor)","FAIL") -> PASS at 95% posterior (prior must be justified to the assessor)
A18: Link to the Annex C / lesson 1 view
A19: Average P(harm | HB) = R̂ / Σ share·λ̂ | B19: =B6/SUMPRODUCT(Scenarios!I6:I105,Scenarios!J6:J105) -> 0.00033895154 | D19: This is the scenario-averaged product P(E|HB)·P(C̄|E)·P(S|C̄) of Annex C.2.
A20: Tolerable overall HB rate R_HB = budget / avg P(harm|HB) | B20: =B11/B19 -> 0.00026552468 | C20: 1/h
A21: Field-only alternative: failure-free hours τ = −ln(1−C)/R_HB | B21: =-LN(1-Inputs!B6)/B20 -> 11282.312 | C21: h | D21: Lesson 1 approach: drive representative hours with zero unintended brakes. Compare with the replay hours in HB Evidence.
A22: Unknown-trigger reserve: field hours with no unexplained HB | B22: =-LN(1-Inputs!B6)/(Inputs!B7*Inputs!B5/B19) -> 101540.81 | C22: h | D22: Every HB in this field driving must map to a known trigger; an unexplained one counts against ε·A_H.
A23: Replay hours used so far | B23: ='HB Evidence'!D27 -> 73500 | C23: h
A25: Point risk by trigger context | B25: R̂ [1/h] | C25: Share | D25: Share if λ were known (synthetic truth)
A26: Clear road, no trigger | B26: =SUMIF(Scenarios!$B$6:$B$105,A26,Scenarios!$R$6:$R$105) -> 0 | C26: =B26/$B$6 -> 0 | D26: =SUMIF(Scenarios!$B$6:$B$105,A26,Scenarios!$X$6:$X$105)/SUM(Scenarios!$X$6:$X$105) -> 0.18127038
A27: Overhead structure (bridge, gantry) | B27: =SUMIF(Scenarios!$B$6:$B$105,A27,Scenarios!$R$6:$R$105) -> 5.2187854e-09 | C27: =B27/$B$6 -> 0.25240735 | D27: =SUMIF(Scenarios!$B$6:$B$105,A27,Scenarios!$X$6:$X$105)/SUM(Scenarios!$X$6:$X$105) -> 0.20981164
A28: Low sun / hard shadow | B28: =SUMIF(Scenarios!$B$6:$B$105,A28,Scenarios!$R$6:$R$105) -> 3.9577985e-09 | C28: =B28/$B$6 -> 0.19141953 | D28: =SUMIF(Scenarios!$B$6:$B$105,A28,Scenarios!$X$6:$X$105)/SUM(Scenarios!$X$6:$X$105) -> 0.15226384
A29: Spray / heavy rain | B29: =SUMIF(Scenarios!$B$6:$B$105,A29,Scenarios!$R$6:$R$105) -> 7.9186832e-09 | C29: =B29/$B$6 -> 0.38298832 | D29: =SUMIF(Scenarios!$B$6:$B$105,A29,Scenarios!$X$6:$X$105)/SUM(Scenarios!$X$6:$X$105) -> 0.35143948
A30: Roadside clutter / debris | B30: =SUMIF(Scenarios!$B$6:$B$105,A30,Scenarios!$R$6:$R$105) -> 3.5807766e-09 | C30: =B30/$B$6 -> 0.17318481 | D30: =SUMIF(Scenarios!$B$6:$B$105,A30,Scenarios!$X$6:$X$105)/SUM(Scenarios!$X$6:$X$105) -> 0.10521467
A32: Point risk by follower headway | B32: R̂ [1/h] | C32: Share | D32: Share if λ were known (synthetic truth)
A33: No follower within 3 s | B33: =SUMIF(Scenarios!$D$6:$D$105,A33,Scenarios!$R$6:$R$105) -> 0 | C33: =B33/$B$6 -> 0 | D33: =SUMIF(Scenarios!$D$6:$D$105,A33,Scenarios!$X$6:$X$105)/SUM(Scenarios!$X$6:$X$105) -> 0
A34: Follower 2–3 s | B34: =SUMIF(Scenarios!$D$6:$D$105,A34,Scenarios!$R$6:$R$105) -> 2.2377787e-10 | C34: =B34/$B$6 -> 0.010823051 | D34: =SUMIF(Scenarios!$D$6:$D$105,A34,Scenarios!$X$6:$X$105)/SUM(Scenarios!$X$6:$X$105) -> 0.0084010771
A35: Follower 1.5–2 s | B35: =SUMIF(Scenarios!$D$6:$D$105,A35,Scenarios!$R$6:$R$105) -> 8.8088397e-10 | C35: =B35/$B$6 -> 0.042604087 | D35: =SUMIF(Scenarios!$D$6:$D$105,A35,Scenarios!$X$6:$X$105)/SUM(Scenarios!$X$6:$X$105) -> 0.060001006
A36: Follower 1–1.5 s | B36: =SUMIF(Scenarios!$D$6:$D$105,A36,Scenarios!$R$6:$R$105) -> 6.7819252e-09 | C36: =B36/$B$6 -> 0.32800885 | D36: =SUMIF(Scenarios!$D$6:$D$105,A36,Scenarios!$X$6:$X$105)/SUM(Scenarios!$X$6:$X$105) -> 0.31742989
A37: Follower < 1 s | B37: =SUMIF(Scenarios!$D$6:$D$105,A37,Scenarios!$R$6:$R$105) -> 1.2789457e-08 | C37: =B37/$B$6 -> 0.61856402 | D37: =SUMIF(Scenarios!$D$6:$D$105,A37,Scenarios!$X$6:$X$105)/SUM(Scenarios!$X$6:$X$105) -> 0.61416802
A39: Point risk by speed band | B39: R̂ [1/h] | C39: Share | D39: Share if λ were known (synthetic truth)
A40: 20–35 km/h | B40: =SUMIF(Scenarios!$C$6:$C$105,A40,Scenarios!$R$6:$R$105) -> 1.7008449e-08 | C40: =B40/$B$6 -> 0.82261623 | D40: =SUMIF(Scenarios!$C$6:$C$105,A40,Scenarios!$X$6:$X$105)/SUM(Scenarios!$X$6:$X$105) -> 0.4984316
A41: 35–55 km/h | B41: =SUMIF(Scenarios!$C$6:$C$105,A41,Scenarios!$R$6:$R$105) -> 1.6843687e-09 | C41: =B41/$B$6 -> 0.081464748 | D41: =SUMIF(Scenarios!$C$6:$C$105,A41,Scenarios!$X$6:$X$105)/SUM(Scenarios!$X$6:$X$105) -> 0.3917113
A42: 55–75 km/h | B42: =SUMIF(Scenarios!$C$6:$C$105,A42,Scenarios!$R$6:$R$105) -> 1.1398645e-09 | C42: =B42/$B$6 -> 0.055129718 | D42: =SUMIF(Scenarios!$C$6:$C$105,A42,Scenarios!$X$6:$X$105)/SUM(Scenarios!$X$6:$X$105) -> 0.082634948
A43: 75–95 km/h | B43: =SUMIF(Scenarios!$C$6:$C$105,A43,Scenarios!$R$6:$R$105) -> 8.433614e-10 | C43: =B43/$B$6 -> 0.040789302 | D43: =SUMIF(Scenarios!$C$6:$C$105,A43,Scenarios!$X$6:$X$105)/SUM(Scenarios!$X$6:$X$105) -> 0.027222152
A45: Screening: scenarios whose bound share·λ_U ≤ 0.1% of budget (safe to skip simulation) | B45: =COUNTIF(Scenarios!U6:U105,"<="&B11*0.001) -> 0
A46: Sum of their screening bounds | B46: =SUMIF(Scenarios!U6:U105,"<="&B11*0.001) -> 0 | C46: 1/h
A48: Reality check (synthetic truth — unknowable in practice)
...

Sheet Validation Targets
A1: Validation targets per evidence cell
A2: How many replay hours each cell needs so the Bonferroni bound fits the budget.
A3: Optimal allocation: minimise total hours Σ λ_k,j·G_j/B_j subject to Σ B_j = budget ⇒ B_j ∝ √(λ_k,j·G_j) (Lagrange multiplier; λ_k,j = ½χ²_2(k_j+1)(C_b) differs per cell because k_j differs). Required hours assume no further events (observed k kept).
A5: Cell | B5: Trigger context | C5: Speed band | D5: Harm weight G_j | E5: Events k so far | F5: Hours so far | G5: Budget B_j (optimal, ∝ √(λ_k·G)) | H5: λ target = B_j/G_j [1/h] | I5: Required hours (optimal) | J5: Additional hours | K5: Budget B_j (equal split) | L5: Required hours (equal) | M5: λ_k,j(C_b) = ½χ²
A6: ='HB Evidence'!A6 -> T1S1 | B6: ='HB Evidence'!B6 -> Clear road, no trigger | C6: ='HB Evidence'!C6 -> 20–35 km/h | D6: ='HB Evidence'!J6 -> 0.00017961987 | E6: ='HB Evidence'!E6 -> 0 | F6: ='HB Evidence'!D6 -> 12000 | G6: =Inputs!$B$11*SQRT(M6*D6)/SUMPRODUCT(SQRT($M$6:$M$25*$D$6:$D$25)) -> 1.4935043e-08 | H6: =G6/D6 -> 8.3148055e-05 | I6: =M6/H6 -> 93606.808 | J6: =MAX(0,I6-F6) -> 81606.808 | K6: =Inputs!$B$11/20 -> 4.5e-09 | L6: =CHIINV(1-Inputs!$B$10,2*(E6+1))/2/(K6/D6) -> 310671.49 | M6: =CHIINV(1-Inputs!$B$10,2*(E6+1))/2 -> 7.783224
A7: ='HB Evidence'!A7 -> T1S2 | B7: ='HB Evidence'!B7 -> Clear road, no trigger | C7: ='HB Evidence'!C7 -> 35–55 km/h | D7: ='HB Evidence'!J7 -> 0.00018368472 | E7: ='HB Evidence'!E7 -> 0 | F7: ='HB Evidence'!D7 -> 14000 | G7: =Inputs!$B$11*SQRT(M7*D7)/SUMPRODUCT(SQRT($M$6:$M$25*$D$6:$D$25)) -> 1.510309e-08 | H7: =G7/D7 -> 8.2222896e-05 | I7: =M7/H7 -> 94660.057 | J7: =MAX(0,I7-F7) -> 80660.057 | K7: =Inputs!$B$11/20 -> 4.5e-09 | L7: =CHIINV(1-Inputs!$B$10,2*(E7+1))/2/(K7/D7) -> 317702.07 | M7: =CHIINV(1-Inputs!$B$10,2*(E7+1))/2 -> 7.783224
A8: ='HB Evidence'!A8 -> T1S3 | B8: ='HB Evidence'!B8 -> Clear road, no trigger | C8: ='HB Evidence'!C8 -> 55–75 km/h | D8: ='HB Evidence'!J8 -> 3.8232587e-05 | E8: ='HB Evidence'!E8 -> 0 | F8: ='HB Evidence'!D8 -> 6000 | G8: =Inputs!$B$11*SQRT(M8*D8)/SUMPRODUCT(SQRT($M$6:$M$25*$D$6:$D$25)) -> 6.8904268e-09 | H8: =G8/D8 -> 0.00018022392 | I8: =M8/H8 -> 43186.409 | J8: =MAX(0,I8-F8) -> 37186.409 | K8: =Inputs!$B$11/20 -> 4.5e-09 | L8: =CHIINV(1-Inputs!$B$10,2*(E8+1))/2/(K8/D8) -> 66127.286 | M8: =CHIINV(1-Inputs!$B$10,2*(E8+1))/2 -> 7.783224
A9: ='HB Evidence'!A9 -> T1S4 | B9: ='HB Evidence'!B9 -> Clear road, no trigger | C9: ='HB Evidence'!C9 -> 75–95 km/h | D9: ='HB Evidence'!J9 -> 4.3909283e-05 | E9: ='HB Evidence'!E9 -> 0 | F9: ='HB Evidence'!D9 -> 4000 | G9: =Inputs!$B$11*SQRT(M9*D9)/SUMPRODUCT(SQRT($M$6:$M$25*$D$6:$D$25)) -> 7.3842681e-09 | H9: =G9/D9 -> 0.000168171 | I9: =M9/H9 -> 46281.606 | J9: =MAX(0,I9-F9) -> 42281.606 | K9: =Inputs!$B$11/20 -> 4.5e-09 | L9: =CHIINV(1-Inputs!$B$10,2*(E9+1))/2/(K9/D9) -> 75945.729 | M9: =CHIINV(1-Inputs!$B$10,2*(E9+1))/2 -> 7.783224
A10: ='HB Evidence'!A10 -> T2S1 | B10: ='HB Evidence'!B10 -> Overhead structure (bridge, gantry) | C10: ='HB Evidence'!C10 -> 20–35 km/h | D10: ='HB Evidence'!J10 -> 1.1190566e-05 | E10: ='HB Evidence'!E10 -> 1 | F10: ='HB Evidence'!D10 -> 3000 | G10: =Inputs!$B$11*SQRT(M10*D10)/SUMPRODUCT(SQRT($M$6:$M$25*$D$6:$D$25)) -> 4.2673225e-09 | H10: =G10/D10 -> 0.00038133216 | I10: =M10/H10 -> 26745.852 | J10: =MAX(0,I10-F10) -> 23745.852 | K10: =Inputs!$B$11/20 -> 4.5e-09 | L10: =CHIINV(1-Inputs!$B$10,2*(E10+1))/2/(K10/D10) -> 25362.927 | M10: =CHIINV(1-Inputs!$B$10,2*(E10+1))/2 -> 10.199053
A11: ='HB Evidence'!A11 -> T2S2 | B11: ='HB Evidence'!B11 -> Overhead structure (bridge, gantry) | C11: ='HB Evidence'!C11 -> 35–55 km/h | D11: ='HB Evidence'!J11 -> 1.0105589e-05 | E11: ='HB Evidence'!E11 -> 1 | F11: ='HB Evidence'!D11 -> 4000 | G11: =Inputs!$B$11*SQRT(M11*D11)/SUMPRODUCT(SQRT($M$6:$M$25*$D$6:$D$25)) -> 4.0551811e-09 | H11: =G11/D11 -> 0.00040128104 | I11: =M11/H11 -> 25416.235 | J11: =MAX(0,I11-F11) -> 21416.235 | K11: =Inputs!$B$11/20 -> 4.5e-09 | L11: =CHIINV(1-Inputs!$B$10,2*(E11+1))/2/(K11/D11) -> 22903.875 | M11: =CHIINV(1-Inputs!$B$10,2*(E11+1))/2 -> 10.199053
A12: ='HB Evidence'!A12 -> T2S3 | B12: ='HB Evidence'!B12 -> Overhead structure (bridge, gantry) | C12: ='HB Evidence'!C12 -> 55–75 km/h | D12: ='HB Evidence'!J12 -> 1.7291049e-06 | E12: ='HB Evidence'!E12 -> 1 | F12: ='HB Evidence'!D12 -> 2500 | G12: =Inputs!$B$11*SQRT(M12*D12)/SUMPRODUCT(SQRT($M$6:$M$25*$D$6:$D$25)) -> 1.6774134e-09 | H12: =G12/D12 -> 0.00097010508 | I12: =M12/H12 -> 10513.349 | J12: =MAX(0,I12-F12) -> 8013.349 | K12: =Inputs!$B$11/20 -> 4.5e-09 | L12: =CHIINV(1-Inputs!$B$10,2*(E12+1))/2/(K12/D12) -> 3918.9406 | M12: =CHIINV(1-Inputs!$B$10,2*(E12+1))/2 -> 10.199053
A13: ='HB Evidence'!A13 -> T2S4 | B13: ='HB Evidence'!B13 -> Overhead structure (bridge, gantry) | C13: ='HB Evidence'!C13 -> 75–95 km/h | D13: ='HB Evidence'!J13 -> 4.1401308e-07 | E13: ='HB Evidence'!E13 -> 4 | F13: ='HB Evidence'!D13 -> 2000 | G13: =Inputs!$B$11*SQRT(M13*D13)/SUMPRODUCT(SQRT($M$6:$M$25*$D$6:$D$25)) -> 1.0263901e-09 | H13: =G13/D13 -> 0.0024791249 | I13: =M13/H13 -> 6432.9983 | J13: =MAX(0,I13-F13) -> 4432.9983 | K13: =Inputs!$B$11/20 -> 4.5e-09 | L13: =CHIINV(1-Inputs!$B$10,2*(E13+1))/2/(K13/D13) -> 1467.2814 | M13: =CHIINV(1-Inputs!$B$10,2*(E13+1))/2 -> 15.948206
A14: ='HB Evidence'!A14 -> T3S1 | B14: ='HB Evidence'!B14 -> Low sun / hard shadow | C14: ='HB Evidence'!C14 -> 20–35 km/h | D14: ='HB Evidence'!J14 -> 1.5566362e-05 | E14: ='HB Evidence'!E14 -> 1 | F14: ='HB Evidence'!D14 -> 3000 | G14: =Inputs!$B$11*SQRT(M14*D14)/SUMPRODUCT(SQRT($M$6:$M$25*$D$6:$D$25)) -> 5.0329546e-09 | H14: =G14/D14 -> 0.00032332246 | I14: =M14/H14 -> 31544.524 | J14: =MAX(0,I14-F14) -> 28544.524 | K14: =Inputs!$B$11/20 -> 4.5e-09 | L14: =CHIINV(1-Inputs!$B$10,2*(E14+1))/2/(K14/D14) -> 35280.48 | M14: =CHIINV(1-Inputs!$B$10,2*(E14+1))/2 -> 10.199053
A15: ='HB Evidence'!A15 -> T3S2 | B15: ='HB Evidence'!B15 -> Low sun / hard shadow | C15: ='HB Evidence'!C15 -> 35–55 km/h | D15: ='HB Evidence'!J15 -> 1.6647479e-05 | E15: ='HB Evidence'!E15 -> 0 | F15: ='HB Evidence'!D15 -> 3500 | G15: =Inputs!$B$11*SQRT(M15*D15)/SUMPRODUCT(SQRT($M$6:$M$25*$D$6:$D$25)) -> 4.5467756e-09 | H15: =G15/D15 -> 0.00027312097 | I15: =M15/H15 -> 28497.35 | J15: =MAX(0,I15-F15) -> 24997.35 | K15: =Inputs!$B$11/20 -> 4.5e-09 | L15: =CHIINV(1-Inputs!$B$10,2*(E15+1))/2/(K15/D15) -> 28793.568 | M15: =CHIINV(1-Inputs!$B$10,2*(E15+1))/2 -> 7.783224
A16: ='HB Evidence'!A16 -> T3S3 | B16: ='HB Evidence'!B16 -> Low sun / hard shadow | C16: ='HB Evidence'!C16 -> 55–75 km/h | D16: ='HB Evidence'!J16 -> 4.7564477e-06 | E16: ='HB Evidence'!E16 -> 0 | F16: ='HB Evidence'!D16 -> 2000 | G16: =Inputs!$B$11*SQRT(M16*D16)/SUMPRODUCT(SQRT($M$6:$M$25*$D$6:$D$25)) -> 2.4303602e-09 | H16: =G16/D16 -> 0.0005109612 | I16: =M16/H16 -> 15232.515 | J16: =MAX(0,I16-F16) -> 13232.515 | K16: =Inputs!$B$11/20 -> 4.5e-09 | L16: =CHIINV(1-Inputs!$B$10,2*(E16+1))/2/(K16/D16) -> 8226.7772 | M16: =CHIINV(1-Inputs!$B$10,2*(E16+1))/2 -> 7.783224
A17: ='HB Evidence'!A17 -> T3S4 | B17: ='HB Evidence'!B17 -> Low sun / hard shadow | C17: ='HB Evidence'!C17 -> 75–95 km/h | D17: ='HB Evidence'!J17 -> 3.1974227e-06 | E17: ='HB Evidence'!E17 -> 0 | F17: ='HB Evidence'!D17 -> 1500 | G17: =Inputs!$B$11*SQRT(M17*D17)/SUMPRODUCT(SQRT($M$6:$M$25*$D$6:$D$25)) -> 1.9926421e-09 | H17: =G17/D17 -> 0.0006232026 | I17: =M17/H17 -> 12489.075 | J17: =MAX(0,I17-F17) -> 10989.075 | K17: =Inputs!$B$11/20 -> 4.5e-09 | L17: =CHIINV(1-Inputs!$B$10,2*(E17+1))/2/(K17/D17) -> 5530.2793 | M17: =CHIINV(1-Inputs!$B$10,2*(E17+1))/2 -> 7.783224
... A25: ='HB Evidence'!A25 -> T5S4 | B25: ='HB Evidence'!B25 -> Roadside clutter / debris | C25: ='HB Evidence'!C25 -> 75–95 km/h | D25: ='HB Evidence'!J25 -> 8.9151066e-07 | E25: ='HB Evidence'!E25 -> 2 | F25: ='HB Evidence'!D25 -> 1000 | G25: =Inputs!$B$11*SQRT(M25*D25)/SUMPRODUCT(SQRT($M$6:$M$25*$D$6:$D$25)) -> 1.3208924e-09 | H25: =G25/D25 -> 0.0014816338 | I25: =M25/H25 -> 8278.8191 | J25: =MAX(0,I25-F25) -> 7278.8191 | K25: =Inputs!$B$11/20 -> 4.5e-09 | L25: =CHIINV(1-Inputs!$B$10,2*(E25+1))/2/(K25/D25) -> 2430.0953 | M25: =CHIINV(1-Inputs!$B$10,2*(E25+1))/2 -> 12.266178
C27: Totals | F27: =SUM(F6:F25) -> 73500 | I27: =SUM(I6:I25) -> 564083.6 | J27: =SUM(J6:J25) -> 490583.6 | L27: =SUM(L6:L25) -> 993870
A29: Caveats
A30: 1. G_j uses the Bonferroni upper collision probability, so it also shrinks as you add simulation runs — the two evidence types trade off.
